Workbook

Sheet Standard Sequences
A1: Standard Sequences
C3: Unused/Unnecessary | D3: Tested | E3: Runs / Ready for Invivo Validation | F3: Errors
A5: Sequence | B5: XD | C5: Pulse Sequence | D5: PSD | E5: Options | F5: FOV | G5: Xres | H5: Yres | I5: Zres | J5: TE | K5: TR | L5: Flip Angle
A6: anatgx_cpir_25MRSI | B6: 3 | C6: SPGR | E6: Fast | F6: 25 | G6: 5 | H6: 5 | I6: 5 | J6: 0.536 | K6: 1.3 | L6: 3
A7: anatgx_cpir_30MRSI | B7: 3 | C7: SPGR | E7: Fast | F7: 30 | G7: 5 | H7: 5 | I7: 5 | J7: 0.488 | K7: 1.3 | L7: 3
A8: anatgx_cpir_35MRSI | B8: 3 | C8: SPGR | E8: Fast | F8: 35 | G8: 5 | H8: 5 | I8: 5 | J8: 0.476 | K8: 1.3 | L8: 3
A9: anatgx_cpir_40MRSI | B9: 3 | C9: SPGR | E9: Fast | F9: 40 | G9: 5 | H9: 5 | I9: 5 | J9: 0.456 | K9: 1.3 | L9: 3
A10: anatgx_mnsrp_3dMRSI | B10: 2 | C10: Fast GRE | E10: EDR | F10: 30 | G10: =300/72 -> 4.1666667 | H10: =267/64 -> 4.171875 | I10: 4.2 | J10: 1.204 | K10: 3.3 | L10: 10
A11: anatvent_xectc_20cart | B11: 2 | C11: Fast GRE | E11: EDR,SqP | F11: 20 | G11: 2 | H11: 2 | I11: 15 | J11: 1.028 | K11: 3.2 | L11: 10
A12: anatvent_xectc_30cart | B12: 2 | C12: Fast GRE | E12: EDR,SqP | F12: 30 | G12: 2 | H12: 2 | I12: 15 | J12: 1.02 | K12: 3.3 | L12: 10
A13: anatvent_xectc_40cart | B13: 2 | C13: Fast GRE | E13: EDR,SqP | F13: 40 | G13: 2 | H13: 2 | I13: 15 | J13: 1.04 | K13: 3.5 | L13: 10
A14: cardiac_cpir_3Vflow | B14: 2 | C14: Vasc PC | E14: FC,Gat,Seq,EDR,Fast,Asset | F14: 30 | G14: =300/120 -> 2.5 | H14: =300/120 -> 2.5 | I14: 8 | J14: 2.8 | K14: 4.7 | L14: 10
A15: cardiac_cpir_4dFlow | B15: 3 | C15: 4DFLOW | E15: Gat,EDR,Fast,ARC | F15: 25 | G15: =250/128 -> 1.953125 | H15: =250/128 -> 1.953125 | I15: 2 | J15: 1.6 | K15: 3.6 | L15: 10
A16: Cor_GRE_Phantom_Noise | B16: 2 | C16: Fid CSI | D16: fidcsi2 | E16: EDR | F16: 48 | G16: =480/64 -> 7.5 | H16: =480/32 -> 15 | I16: 250 | J16: 0 | K16: 19.2 | L16: 1
A17: Cor_GRE_Phantom_Signal | B17: 2 | C17: Fid CSI | D17: fidcsi2 | E17: EDR | F17: 48 | G17: =480/64 -> 7.5 | H17: =480/32 -> 15 | I17: 250 | J17: 0 | K17: 750 | L17: 74
A18: preful_cpir_ffe | B18: 2 | C18: SPGR | E18: Seq,EDR,Fast,MPh,ARC | F18: 50 | G18: =500/128 -> 3.90625 | H18: =500/128 -> 3.90625 | I18: 15 | J18: 0.744 | K18: 2.116 | L18: 5
A19: Proton_3D_GRE | B19: 3 | C19: SPGR | E19: Fast | F19: 40 | G19: =400/64 -> 6.25 | H19: =400/64 -> 6.25 | I19: 6.25 | J19: 0.456 | K19: 1.6 | L19: 3
A20: Proton_Cor_GRE | B20: 2 | C20: Gradient Echo | E20: Seq,Fast,Sqp,ZIP512 | F20: 38.4 | G20: =384/96 -> 4 | H20: =384/96 -> 4 | I20: 15 | J20: 1.088 | K20: 4.5 | L20: 10
A21: qa_cpir_FID | B21: 2 | C21: Fid CSI | E21: EDR | F21: 45 | J21: 0 | K21: 4000 | L21: 90
A22: qa_polarean_image | B22: 2 | C22: Fid CSI | D22: fidcsi2 | E22: EDR | F22: 48 | G22: =480/64 -> 7.5 | H22: =480/32 -> 15 | I22: 250 | J22: 0 | K22: 750 | L22: 74
A23: Scout_Localizer_3-plane | B23: 2 | C23: Gradient Echo | E23: Seq,Fast | F23: 50 | G23: =500/256 -> 1.953125 | H23: =500/128 -> 3.90625 | I23: 15 | J23: 1.084 | K23: 4.436 | L23: 30
A24: stru_cpir_4dzte | B24: 3 | C24: Gradient Echo | D24: research/ZTE4D/3dradial | E24: EDR,Fast,SqP,ZIP512 | F24: 35 | G24: =350/220 -> 1.5909091 | H24: =350/220 -> 1.5909091 | I24: 1.6 | J24: 0.016 | K24: 200.28 | L24: 2
A25: sur_cpir_card2pcv | B25: 2 | C25: Fiesta | E25: Gat,Seq,EDR,Fast,SqP,ZIP512,SonicDL | F25: 36 | G25: =360/192 -> 1.875 | H25: =360/160 -> 2.25 | I25: =8 -> 8 | J25: 0.9 | K25: 2.6 | L25: 49
A26: sur_cpir_cardSACine | B26: 2 | C26: Fiesta | E26: Gat,Seq,EDR,Fast,SqP,ZIP512,SonicDL | F26: 36 | G26: =360/192 -> 1.875 | H26: =360/160 -> 2.25 | I26: =8 -> 8 | J26: 0.9 | K26: 2.6 | L26: 49
A27: sur_cpir_Localizer | B27: 2 | C27: Gradient Echo | E27: Seq,Fast | F27: 50 | G27: =500/256 -> 1.953125 | H27: =500/128 -> 3.90625 | I27: 15 | J27: 1.084 | K27: 4.436 | L27: 30
A28: vent_xectc_20cart | B28: 2 | C28: Fid CSI | D28: fidcsi2 | E28: EDR | F28: 20 | G28: 4 | H28: 4 | I28: 15 | J28: 0 | K28: 123.6 | L28: 10
A29: vent_xectc_30cart | B29: 2 | C29: Fid CSI | D29: fidcsi2 | E29: EDR | F29: 30 | G29: 4 | H29: 4 | I29: 15 | J29: 0 | K29: 145.5 | L29: 10
A30: vent_xectc_40cart | B30: 2 | C30: Fid CSI | D30: fidcsi2 | E30: EDR | F30: 40 | G30: 4 | H30: 4 | I30: 15 | J30: 0 | K30: 155.9 | L30: 10
A31: Xenon_Cor_GRE_Ventilation | B31: 2 | C31: Fid CSI | D31: fidcsi2 | E31: EDR | F31: 38.4 | G31: =384/96 -> 4 | H31: =384/96 -> 4 | I31: 15 | J31: 0 | K31: 124.7 | L31: 10

Sheet MNSRP Sequences
A1: Sequence Name | B1: Flip Angle | C1: TE | D1: TR | E1: CV3 - Scan Mode | F1: ak_grad | G1: recon26 | H1: CV4 - Total number of scans | I1: CV14 - rfpulse | J1: exrf | K1: CV19 - blosi | L1: CV20 - vap | M1: vap_ | N1: cv21 - cv_pars | O1: cv_pars_ | P1: Notes
A2: qa_cpir_PhantomCSI | B2: 19 | C2: 0.746 | D2: 58.1 | E2: 1 | F2: =IF(_xlfn.XLOOKUP(Table1[[#This Row],[CV3 - Scan Mode]],'ak_grad links'!A:A,'ak_grad links'!B:B)=0,"",_xlfn.XLOOKUP(Table1[[#This Row],[CV3 - Scan Mode]],'ak_grad links'!A:A,'ak_grad links'!B:B)) -> MRSI Mode | G2: =IF(_xlfn.XLOOKUP(Table1[[#This Row],[CV3 - Scan Mode]],'recon links'!A:A,'recon links'!B:B)=0,"",_xlfn.XLOOKUP(Table1[[#This Row],[CV3 - Scan Mode]],'recon links'!A:A,'recon links'!B:B)) -> /export/home/sdc/fidall/bin/stack_plot.py /export/home/sdc/fidall/bin/recon_csi.py /export/home/sdc/fidall/bin/recon_prescan.py | H2: 1 | I2: 0 | J2: =IF(_xlfn.XLOOKUP(Table1[[#This Row],[CV14 - rfpulse]],'rf links'!A:A,'rf links'!E:E)=0,"",_xlfn.XLOOKUP(Table1[[#This Row],[CV14 - rfpulse]],'rf links'!A:A,'rf links'!E:E)) -> GE hard pulse | K2: 0 | L2: 0 | M2: =IF(_xlfn.XLOOKUP(Table1[[#This Row],[CV20 - vap]],'vap links'!A:A,'vap links'!K:K)=0,"",_xlfn.XLOOKUP(Table1[[#This Row],[CV20 - vap]],'vap links'!A:A,'vap links'!K:K)) -> #N/A | N2: 0 | O2: =IF(_xlfn.XLOOKUP(Table1[[#This Row],[cv21 - cv_pars]],'cv_pars links'!A:A,'cv_pars links'!B:B)=0,"",_xlfn.XLOOKUP(Table1[[#This Row],[cv21 - cv_pars]],'cv_pars links'!A:A,'cv_pars links'!B:B)) -> #N/A
A3: qa_mnsrp_SystemNoise | B3: 90 | C3: 0.455 | D3: 74.6 | E3: 1 | F3: =IF(_xlfn.XLOOKUP(Table1[[#This Row],[CV3 - Scan Mode]],'ak_grad links'!A:A,'ak_grad links'!B:B)=0,"",_xlfn.XLOOKUP(Table1[[#This Row],[CV3 - Scan Mode]],'ak_grad links'!A:A,'ak_grad links'!B:B)) -> MRSI Mode | G3: =IF(_xlfn.XLOOKUP(Table1[[#This Row],[CV3 - Scan Mode]],'recon links'!A:A,'recon links'!B:B)=0,"",_xlfn.XLOOKUP(Table1[[#This Row],[CV3 - Scan Mode]],'recon links'!A:A,'recon links'!B:B)) -> /export/home/sdc/fidall/bin/stack_plot.py /export/home/sdc/fidall/bin/recon_csi.py /export/home/sdc/fidall/bin/recon_prescan.py | H3: 256 | I3: 0 | J3: =IF(_xlfn.XLOOKUP(Table1[[#This Row],[CV14 - rfpulse]],'rf links'!A:A,'rf links'!E:E)=0,"",_xlfn.XLOOKUP(Table1[[#This Row],[CV14 - rfpulse]],'rf links'!A:A,'rf links'!E:E)) -> GE hard pulse | K3: 0 | L3: 0 | M3: =IF(_xlfn.XLOOKUP(Table1[[#This Row],[CV20 - vap]],'vap links'!A:A,'vap links'!K:K)=0,"",_xlfn.XLOOKUP(Table1[[#This Row],[CV20 - vap]],'vap links'!A:A,'vap links'!K:K)) -> #N/A | N3: 0 | O3: =IF(_xlfn.XLOOKUP(Table1[[#This Row],[cv21 - cv_pars]],'cv_pars links'!A:A,'cv_pars links'!B:B)=0,"",_xlfn.XLOOKUP(Table1[[#This Row],[cv21 - cv_pars]],'cv_pars links'!A:A,'cv_pars links'!B:B)) -> #N/A
A4: cal_mnsrp_facal | B4: 10 | C4: 4.67 | D4: 88.8 | E4: 1 | F4: =IF(_xlfn.XLOOKUP(Table1[[#This Row],[CV3 - Scan Mode]],'ak_grad links'!A:A,'ak_grad links'!B:B)=0,"",_xlfn.XLOOKUP(Table1[[#This Row],[CV3 - Scan Mode]],'ak_grad links'!A:A,'ak_grad links'!B:B)) -> MRSI Mode | G4: =IF(_xlfn.XLOOKUP(Table1[[#This Row],[CV3 - Scan Mode]],'recon links'!A:A,'recon links'!B:B)=0,"",_xlfn.XLOOKUP(Table1[[#This Row],[CV3 - Scan Mode]],'recon links'!A:A,'recon links'!B:B)) -> /export/home/sdc/fidall/bin/stack_plot.py /export/home/sdc/fidall/bin/recon_csi.py /export/home/sdc/fidall/bin/recon_prescan.py | H4: 12 | I4: 0 | J4: =IF(_xlfn.XLOOKUP(Table1[[#This Row],[CV14 - rfpulse]],'rf links'!A:A,'rf links'!E:E)=0,"",_xlfn.XLOOKUP(Table1[[#This Row],[CV14 - rfpulse]],'rf links'!A:A,'rf links'!E:E)) -> GE hard pulse | K4: 4 | L4: 0 | M4: =IF(_xlfn.XLOOKUP(Table1[[#This Row],[CV20 - vap]],'vap links'!A:A,'vap links'!K:K)=0,"",_xlfn.XLOOKUP(Table1[[#This Row],[CV20 - vap]],'vap links'!A:A,'vap links'!K:K)) -> #N/A | N4: 12 | O4: =IF(_xlfn.XLOOKUP(Table1[[#This Row],[cv21 - cv_pars]],'cv_pars links'!A:A,'cv_pars links'!B:B)=0,"",_xlfn.XLOOKUP(Table1[[#This Row],[cv21 - cv_pars]],'cv_pars links'!A:A,'cv_pars links'!B:B)) -> cv_pars12.cvs
A5: Xenon_Bloch_Siegert | B5: 10 | C5: 4.914 | D5: 50 | E5: 1 | F5: =IF(_xlfn.XLOOKUP(Table1[[#This Row],[CV3 - Scan Mode]],'ak_grad links'!A:A,'ak_grad links'!B:B)=0,"",_xlfn.XLOOKUP(Table1[[#This Row],[CV3 - Scan Mode]],'ak_grad links'!A:A,'ak_grad links'!B:B)) -> MRSI Mode | G5: =IF(_xlfn.XLOOKUP(Table1[[#This Row],[CV3 - Scan Mode]],'recon links'!A:A,'recon links'!B:B)=0,"",_xlfn.XLOOKUP(Table1[[#This Row],[CV3 - Scan Mode]],'recon links'!A:A,'recon links'!B:B)) -> /export/home/sdc/fidall/bin/stack_plot.py /export/home/sdc/fidall/bin/recon_csi.py /export/home/sdc/fidall/bin/recon_prescan.py | H5: 20 | I5: 52 | J5: =IF(_xlfn.XLOOKUP(Table1[[#This Row],[CV14 - rfpulse]],'rf links'!A:A,'rf links'!E:E)=0,"",_xlfn.XLOOKUP(Table1[[#This Row],[CV14 - rfpulse]],'rf links'!A:A,'rf links'!E:E)) -> rffiles/129Xe_freq_5000hz_600us_3tbw.rho | K5: 4 | L5: 0 | M5: =IF(_xlfn.XLOOKUP(Table1[[#This Row],[CV20 - vap]],'vap links'!A:A,'vap links'!K:K)=0,"",_xlfn.XLOOKUP(Table1[[#This Row],[CV20 - vap]],'vap links'!A:A,'vap links'!K:K)) -> #N/A | N5: 12 | O5: =IF(_xlfn.XLOOKUP(Table1[[#This Row],[cv21 - cv_pars]],'cv_pars links'!A:A,'cv_pars links'!B:B)=0,"",_xlfn.XLOOKUP(Table1[[#This Row],[cv21 - cv_pars]],'cv_pars links'!A:A,'cv_pars links'!B:B)) -> cv_pars12.cvs
A6: vent_mnsrp_2dCartesian | B6: 10.3 | C6: 2.048 | D6: 154 | E6: 15 | F6: =IF(_xlfn.XLOOKUP(Table1[[#This Row],[CV3 - Scan Mode]],'ak_grad links'!A:A,'ak_grad links'!B:B)=0,"",_xlfn.XLOOKUP(Table1[[#This Row],[CV3 - Scan Mode]],'ak_grad links'!A:A,'ak_grad links'!B:B)) -> cart/cart2D_129Xe_fov300x240_mtx100x80_nexc80_kdt20_gmax32_smax99_dur4p92.wav | G6: =IF(_xlfn.XLOOKUP(Table1[[#This Row],[CV3 - Scan Mode]],'recon links'!A:A,'recon links'!B:B)=0,"",_xlfn.XLOOKUP(Table1[[#This Row],[CV3 - Scan Mode]],'recon links'!A:A,'recon links'!B:B)) -> /export/home/sdc/fidall/bin/recon_cart_interp.py | H6: 80 | I6: 1 | J6: =IF(_xlfn.XLOOKUP(Table1[[#This Row],[CV14 - rfpulse]],'rf links'!A:A,'rf links'!E:E)=0,"",_xlfn.XLOOKUP(Table1[[#This Row],[CV14 - rfpulse]],'rf links'!A:A,'rf links'!E:E)) -> GE soft pulse | K6: 0 | L6: 0 | M6: =IF(_xlfn.XLOOKUP(Table1[[#This Row],[CV20 - vap]],'vap links'!A:A,'vap links'!K:K)=0,"",_xlfn.XLOOKUP(Table1[[#This Row],[CV20 - vap]],'vap links'!A:A,'vap links'!K:K)) -> #N/A | N6: 15 | O6: =IF(_xlfn.XLOOKUP(Table1[[#This Row],[cv21 - cv_pars]],'cv_pars links'!A:A,'cv_pars links'!B:B)=0,"",_xlfn.XLOOKUP(Table1[[#This Row],[cv21 - cv_pars]],'cv_pars links'!A:A,'cv_pars links'!B:B)) -> ../waveforms/cart/cv_pars_spgr.cvs
A7: vent_mnsrp_vFA2dCartesian | B7: 30 | C7: 2.048 | D7: 154 | E7: 15 | F7: =IF(_xlfn.XLOOKUP(Table1[[#This Row],[CV3 - Scan Mode]],'ak_grad links'!A:A,'ak_grad links'!B:B)=0,"",_xlfn.XLOOKUP(Table1[[#This Row],[CV3 - Scan Mode]],'ak_grad links'!A:A,'ak_grad links'!B:B)) -> cart/cart2D_129Xe_fov300x240_mtx100x80_nexc80_kdt20_gmax32_smax99_dur4p92.wav | G7: =IF(_xlfn.XLOOKUP(Table1[[#This Row],[CV3 - Scan Mode]],'recon links'!A:A,'recon links'!B:B)=0,"",_xlfn.XLOOKUP(Table1[[#This Row],[CV3 - Scan Mode]],'recon links'!A:A,'recon links'!B:B)) -> /export/home/sdc/fidall/bin/recon_cart_interp.py | H7: 80 | I7: 1 | J7: =IF(_xlfn.XLOOKUP(Table1[[#This Row],[CV14 - rfpulse]],'rf links'!A:A,'rf links'!E:E)=0,"",_xlfn.XLOOKUP(Table1[[#This Row],[CV14 - rfpulse]],'rf links'!A:A,'rf links'!E:E)) -> GE soft pulse | K7: 0 | L7: 15 | M7: =IF(_xlfn.XLOOKUP(Table1[[#This Row],[CV20 - vap]],'vap links'!A:A,'vap links'!K:K)=0,"",_xlfn.XLOOKUP(Table1[[#This Row],[CV20 - vap]],'vap links'!A:A,'vap links'!K:K)) -> ../waveforms/cart/vap_vfa80_30.fdl | N7: 15 | O7: =IF(_xlfn.XLOOKUP(Table1[[#This Row],[cv21 - cv_pars]],'cv_pars links'!A:A,'cv_pars links'!B:B)=0,"",_xlfn.XLOOKUP(Table1[[#This Row],[cv21 - cv_pars]],'cv_pars links'!A:A,'cv_pars links'!B:B)) -> ../waveforms/cart/cv_pars_spgr.cvs
A8: gx_mnsrp_3dMRSI | B8: 10 | C8: 0.357 | D8: 7.9 | E8: 17 | F8: =IF(_xlfn.XLOOKUP(Table1[[#This Row],[CV3 - Scan Mode]],'ak_grad links'!A:A,'ak_grad links'!B:B)=0,"",_xlfn.XLOOKUP(Table1[[#This Row],[CV3 - Scan Mode]],'ak_grad links'!A:A,'ak_grad links'!B:B)) -> mrsi/mrsi3D_129Xe_scheme2_3_fov270_240_150_mtx18_16_10_bw20000_npts88_nexc1586_gmax16_smax87_crush2.wav | G8: =IF(_xlfn.XLOOKUP(Table1[[#This Row],[CV3 - Scan Mode]],'recon links'!A:A,'recon links'!B:B)=0,"",_xlfn.XLOOKUP(Table1[[#This Row],[CV3 - Scan Mode]],'recon links'!A:A,'recon links'!B:B)) -> /export/home/sdc/fidall/bin/recon_mrsi_xenon.py | H8: 1586 | I8: 17 | J8: =IF(_xlfn.XLOOKUP(Table1[[#This Row],[CV14 - rfpulse]],'rf links'!A:A,'rf links'!E:E)=0,"",_xlfn.XLOOKUP(Table1[[#This Row],[CV14 - rfpulse]],'rf links'!A:A,'rf links'!E:E)) -> /export/home/sdc/fidall/waveforms/rffiles/exrf_freq_flip40_t0p6_ref0p5_b1max11p855_bw1000.rho ../waveforms/rffiles/exrf_freq_flip40_t0p6_ref0p5_b1max11p855_bw1000.cvs | K8: 0 | L8: 17 | M8: =IF(_xlfn.XLOOKUP(Table1[[#This Row],[CV20 - vap]],'vap links'!A:A,'vap links'!K:K)=0,"",_xlfn.XLOOKUP(Table1[[#This Row],[CV20 - vap]],'vap links'!A:A,'vap links'!K:K)) -> ../waveforms/mrsi/mrsi3D_129Xe_scheme2_3_fov270_240_150_mtx18_16_10_bw20000_npts88_nexc1586_gmax16_smax87_crush2_agx.fdl ../waveforms/mrsi/mrsi3D_129Xe_scheme2_3_fov270_240_150_mtx18_16_10_bw20000_npts88_nexc1586_gmax16_smax87_crush2_agy.fdl ../waveforms/mrsi/mrsi3D_129Xe_scheme2_3_fov270_240_150_mtx18_16_10_bw20000_npts88_nexc1586_gmax16_smax87_crush2_agz.fdl ../waveforms/mrsi/vap_flip_10deg.fdl | N8: 17 | O8: =IF(_xlfn.XLOOKUP(Table1[[#This Row],[cv21 - cv_pars]],'cv_pars links'!A:A,'cv_pars links'!B:B)=0,"",_xlfn.XLOOKUP(Table1[[#This Row],[cv21 - cv_pars]],'cv_pars links'!A:A,'cv_pars links'!B:B)) -> ../waveforms/mrsi/cv_pars_mrsi_xenon.cvs
A9: qa_mnsrp_GradientNoise | B9: 90 | C9: 2.892 | D9: 1000 | E9: 27 | F9: =IF(_xlfn.XLOOKUP(Table1[[#This Row],[CV3 - Scan Mode]],'ak_grad links'!A:A,'ak_grad links'!B:B)=0,"",_xlfn.XLOOKUP(Table1[[#This Row],[CV3 - Scan Mode]],'ak_grad links'!A:A,'ak_grad links'!B:B)) -> grad_noise/grad_noise_spiral_13C_fov300_ksamp2_gmax30_smax119_dur27p1.wav | G9: =IF(_xlfn.XLOOKUP(Table1[[#This Row],[CV3 - Scan Mode]],'recon links'!A:A,'recon links'!B:B)=0,"",_xlfn.XLOOKUP(Table1[[#This Row],[CV3 - Scan Mode]],'recon links'!A:A,'recon links'!B:B)) -> /export/home/sdc/fidall/bin/characterise_grad_noise.py | H9: 20 | I9: 1 | J9: =IF(_xlfn.XLOOKUP(Table1[[#This Row],[CV14 - rfpulse]],'rf links'!A:A,'rf links'!E:E)=0,"",_xlfn.XLOOKUP(Table1[[#This Row],[CV14 - rfpulse]],'rf links'!A:A,'rf links'!E:E)) -> GE soft pulse | K9: 0 | L9: 27 | M9: =IF(_xlfn.XLOOKUP(Table1[[#This Row],[CV20 - vap]],'vap links'!A:A,'vap links'!K:K)=0,"",_xlfn.XLOOKUP(Table1[[#This Row],[CV20 - vap]],'vap links'!A:A,'vap links'!K:K)) -> ../waveforms/grad_noise/vap_flip_zero.fdl | N9: 27 | O9: =IF(_xlfn.XLOOKUP(Table1[[#This Row],[cv21 - cv_pars]],'cv_pars links'!A:A,'cv_pars links'!B:B)=0,"",_xlfn.XLOOKUP(Table1[[#This Row],[cv21 - cv_pars]],'cv_pars links'!A:A,'cv_pars links'!B:B)) -> ../waveforms/grad_noise/cv_pars_noise.cvs
A10: cal_cpir_dissolved | B10: 20 | C10: 0.384 | D10: 15 | E10: 30 | F10: =IF(_xlfn.XLOOKUP(Table1[[#This Row],[CV3 - Scan Mode]],'ak_grad links'!A:A,'ak_grad links'!B:B)=0,"",_xlfn.XLOOKUP(Table1[[#This Row],[CV3 - Scan Mode]],'ak_grad links'!A:A,'ak_grad links'!B:B)) | G10: =IF(_xlfn.XLOOKUP(Table1[[#This Row],[CV3 - Scan Mode]],'recon links'!A:A,'recon links'!B:B)=0,"",_xlfn.XLOOKUP(Table1[[#This Row],[CV3 - Scan Mode]],'recon links'!A:A,'recon links'!B:B)) -> /export/home/sdc/fidall/bin/recon_calibration_cchmc.py | H10: 520 | I10: 30 | J10: =IF(_xlfn.XLOOKUP(Table1[[#This Row],[CV14 - rfpulse]],'rf links'!A:A,'rf links'!E:E)=0,"",_xlfn.XLOOKUP(Table1[[#This Row],[CV14 - rfpulse]],'rf links'!A:A,'rf links'!E:E)) -> rffiles/129Xe_freq_5000hz_600us_3tbw.rho | K10: 0 | L10: 30 | M10: =IF(_xlfn.XLOOKUP(Table1[[#This Row],[CV20 - vap]],'vap links'!A:A,'vap links'!K:K)=0,"",_xlfn.XLOOKUP(Table1[[#This Row],[CV20 - vap]],'vap links'!A:A,'vap links'!K:K)) -> ../waveforms/cal/cal_cpir_nexc520_ndiss500_dfreq202_freq.fdl ../waveforms/vap_rf_spoiling/vap_phase_rf_spoiling_262112.fdl | N10: 30 | O10: =IF(_xlfn.XLOOKUP(Table1[[#This Row],[cv21 - cv_pars]],'cv_pars links'!A:A,'cv_pars links'!B:B)=0,"",_xlfn.XLOOKUP(Table1[[#This Row],[cv21 - cv_pars]],'cv_pars links'!A:A,'cv_pars links'!B:B)) -> ../waveforms/cal/cal_xxx.cvs | P10: revalidate in vivo, confirm accurate dissolved fits
A11: cal_xectc_dissolved | B11: 20 | C11: 0.384 | D11: 15 | E11: 31 | F11: =IF(_xlfn.XLOOKUP(Table1[[#This Row],[CV3 - Scan Mode]],'ak_grad links'!A:A,'ak_grad links'!B:B)=0,"",_xlfn.XLOOKUP(Table1[[#This Row],[CV3 - Scan Mode]],'ak_grad links'!A:A,'ak_grad links'!B:B)) | G11: =IF(_xlfn.XLOOKUP(Table1[[#This Row],[CV3 - Scan Mode]],'recon links'!A:A,'recon links'!B:B)=0,"",_xlfn.XLOOKUP(Table1[[#This Row],[CV3 - Scan Mode]],'recon links'!A:A,'recon links'!B:B)) -> /export/home/sdc/fidall/bin/recon_calibration_cchmc.py | H11: 520 | I11: 31 | J11: =IF(_xlfn.XLOOKUP(Table1[[#This Row],[CV14 - rfpulse]],'rf links'!A:A,'rf links'!E:E)=0,"",_xlfn.XLOOKUP(Table1[[#This Row],[CV14 - rfpulse]],'rf links'!A:A,'rf links'!E:E)) -> rffiles/129Xe_freq_5000hz_600us_3tbw.rho | K11: 0 | L11: 31 | M11: =IF(_xlfn.XLOOKUP(Table1[[#This Row],[CV20 - vap]],'vap links'!A:A,'vap links'!K:K)=0,"",_xlfn.XLOOKUP(Table1[[#This Row],[CV20 - vap]],'vap links'!A:A,'vap links'!K:K)) -> ../waveforms/cal/cal_xectc_nexc520_ndiss500_dfreq218_freq.fdl ../waveforms/vap_rf_spoiling/vap_phase_rf_spoiling_262112.fdl | N11: 31 | O11: =IF(_xlfn.XLOOKUP(Table1[[#This Row],[cv21 - cv_pars]],'cv_pars links'!A:A,'cv_pars links'!B:B)=0,"",_xlfn.XLOOKUP(Table1[[#This Row],[cv21 - cv_pars]],'cv_pars links'!A:A,'cv_pars links'!B:B)) -> ../waveforms/cal/cal_xxx.cvs | P11: validate in vivo
A12: diff_cpir_40Cart4bs2d | B12: 5.5 | C12: 1.776 | D12: 40.6 | E12: 35 | F12: =IF(_xlfn.XLOOKUP(Table1[[#This Row],[CV3 - Scan Mode]],'ak_grad links'!A:A,'ak_grad links'!B:B)=0,"",_xlfn.XLOOKUP(Table1[[#This Row],[CV3 - Scan Mode]],'ak_grad links'!A:A,'ak_grad links'!B:B)) -> diff_cpir_2dCart4bs/diffcart2D_129Xe_fov400_mtx80_nexc320_kdt52_gmax29_smax98_dur14p9_co.wav | G12: =IF(_xlfn.XLOOKUP(Table1[[#This Row],[CV3 - Scan Mode]],'recon links'!A:A,'recon links'!B:B)=0,"",_xlfn.XLOOKUP(Table1[[#This Row],[CV3 - Scan Mode]],'recon links'!A:A,'recon links'!B:B)) -> /export/home/sdc/fidall/bin/recon_diffusion.py | H12: 320 | I12: 1 | J12: =IF(_xlfn.XLOOKUP(Table1[[#This Row],[CV14 - rfpulse]],'rf links'!A:A,'rf links'!E:E)=0,"",_xlfn.XLOOKUP(Table1[[#This Row],[CV14 - rfpulse]],'rf links'!A:A,'rf links'!E:E)) -> GE soft pulse | K12: 0 | L12: 35 | M12: =IF(_xlfn.XLOOKUP(Table1[[#This Row],[CV20 - vap]],'vap links'!A:A,'vap links'!K:K)=0,"",_xlfn.XLOOKUP(Table1[[#This Row],[CV20 - vap]],'vap links'!A:A,'vap links'!K:K)) -> ../waveforms/vap_rf_spoiling/vap_phase_rf_spoiling_262112.fdl | N12: 35 | O12: =IF(_xlfn.XLOOKUP(Table1[[#This Row],[cv21 - cv_pars]],'cv_pars links'!A:A,'cv_pars links'!B:B)=0,"",_xlfn.XLOOKUP(Table1[[#This Row],[cv21 - cv_pars]],'cv_pars links'!A:A,'cv_pars links'!B:B)) -> ../waveforms/diff_cpir_2dCart4bs/diff_cpir_2dCart4bs.cvs
A13: diff_cpir_35Cart4bs2d | B13: 5.8 | C13: 1.776 | D13: 40.6 | E13: 36 | F13: =IF(_xlfn.XLOOKUP(Table1[[#This Row],[CV3 - Scan Mode]],'ak_grad links'!A:A,'ak_grad links'!B:B)=0,"",_xlfn.XLOOKUP(Table1[[#This Row],[CV3 - Scan Mode]],'ak_grad links'!A:A,'ak_grad links'!B:B)) -> diff_cpir_2dCart4bs/diffcart2D_129Xe_fov350_mtx70_nexc280_kdt52_gmax29_smax98_dur14p3_co.wav | G13: =IF(_xlfn.XLOOKUP(Table1[[#This Row],[CV3 - Scan Mode]],'recon links'!A:A,'recon links'!B:B)=0,"",_xlfn.XLOOKUP(Table1[[#This Row],[CV3 - Scan Mode]],'recon links'!A:A,'recon links'!B:B)) -> /export/home/sdc/fidall/bin/recon_diffusion.py | H13: 280 | I13: 1 | J13: =IF(_xlfn.XLOOKUP(Table1[[#This Row],[CV14 - rfpulse]],'rf links'!A:A,'rf links'!E:E)=0,"",_xlfn.XLOOKUP(Table1[[#This Row],[CV14 - rfpulse]],'rf links'!A:A,'rf links'!E:E)) -> GE soft pulse | K13: 0 | L13: 36 | M13: =IF(_xlfn.XLOOKUP(Table1[[#This Row],[CV20 - vap]],'vap links'!A:A,'vap links'!K:K)=0,"",_xlfn.XLOOKUP(Table1[[#This Row],[CV20 - vap]],'vap links'!A:A,'vap links'!K:K)) -> ../waveforms/vap_rf_spoiling/vap_phase_rf_spoiling_262112.fdl | N13: 36 | O13: =IF(_xlfn.XLOOKUP(Table1[[#This Row],[cv21 - cv_pars]],'cv_pars links'!A:A,'cv_pars links'!B:B)=0,"",_xlfn.XLOOKUP(Table1[[#This Row],[cv21 - cv_pars]],'cv_pars links'!A:A,'cv_pars links'!B:B)) -> ../waveforms/diff_cpir_2dCart4bs/diff_cpir_2dCart4bs.cvs
A14: diff_cpir_30Cart4bs2d | B14: 6.2 | C14: 1.776 | D14: 60.9 | E14: 37 | F14: =IF(_xlfn.XLOOKUP(Table1[[#This Row],[CV3 - Scan Mode]],'ak_grad links'!A:A,'ak_grad links'!B:B)=0,"",_xlfn.XLOOKUP(Table1[[#This Row],[CV3 - Scan Mode]],'ak_grad links'!A:A,'ak_grad links'!B:B)) -> diff_cpir_2dCart4bs/diffcart2D_129Xe_fov300_mtx60_nexc240_kdt52_gmax29_smax98_dur13p8_co.wav | G14: =IF(_xlfn.XLOOKUP(Table1[[#This Row],[CV3 - Scan Mode]],'recon links'!A:A,'recon links'!B:B)=0,"",_xlfn.XLOOKUP(Table1[[#This Row],[CV3 - Scan Mode]],'recon links'!A:A,'recon links'!B:B)) -> /export/home/sdc/fidall/bin/recon_diffusion.py | H14: 240 | I14: 1 | J14: =IF(_xlfn.XLOOKUP(Table1[[#This Row],[CV14 - rfpulse]],'rf links'!A:A,'rf links'!E:E)=0,"",_xlfn.XLOOKUP(Table1[[#This Row],[CV14 - rfpulse]],'rf links'!A:A,'rf links'!E:E)) -> GE soft pulse | K14: 0 | L14: 37 | M14: =IF(_xlfn.XLOOKUP(Table1[[#This Row],[CV20 - vap]],'vap links'!A:A,'vap links'!K:K)=0,"",_xlfn.XLOOKUP(Table1[[#This Row],[CV20 - vap]],'vap links'!A:A,'vap links'!K:K)) -> ../waveforms/vap_rf_spoiling/vap_phase_rf_spoiling_262112.fdl | N14: 37 | O14: =IF(_xlfn.XLOOKUP(Table1[[#This Row],[cv21 - cv_pars]],'cv_pars links'!A:A,'cv_pars links'!B:B)=0,"",_xlfn.XLOOKUP(Table1[[#This Row],[cv21 - cv_pars]],'cv_pars links'!A:A,'cv_pars links'!B:B)) -> ../waveforms/diff_cpir_2dCart4bs/diff_cpir_2dCart4bs.cvs
A15: diff_cpir_25Cart4bs2d | B15: 6.8 | C15: 1.776 | D15: 81.2 | E15: 38 | F15: =IF(_xlfn.XLOOKUP(Table1[[#This Row],[CV3 - Scan Mode]],'ak_grad links'!A:A,'ak_grad links'!B:B)=0,"",_xlfn.XLOOKUP(Table1[[#This Row],[CV3 - Scan Mode]],'ak_grad links'!A:A,'ak_grad links'!B:B)) -> diff_cpir_2dCart4bs/diffcart2D_129Xe_fov250_mtx50_nexc200_kdt52_gmax29_smax98_dur13p4_co.wav | G15: =IF(_xlfn.XLOOKUP(Table1[[#This Row],[CV3 - Scan Mode]],'recon links'!A:A,'recon links'!B:B)=0,"",_xlfn.XLOOKUP(Table1[[#This Row],[CV3 - Scan Mode]],'recon links'!A:A,'recon links'!B:B)) -> /export/home/sdc/fidall/bin/recon_diffusion.py | H15: 200 | I15: 1 | J15: =IF(_xlfn.XLOOKUP(Table1[[#This Row],[CV14 - rfpulse]],'rf links'!A:A,'rf links'!E:E)=0,"",_xlfn.XLOOKUP(Table1[[#This Row],[CV14 - rfpulse]],'rf links'!A:A,'rf links'!E:E)) -> GE soft pulse | K15: 0 | L15: 38 | M15: =IF(_xlfn.XLOOKUP(Table1[[#This Row],[CV20 - vap]],'vap links'!A:A,'vap links'!K:K)=0,"",_xlfn.XLOOKUP(Table1[[#This Row],[CV20 - vap]],'vap links'!A:A,'vap links'!K:K)) -> ../waveforms/vap_rf_spoiling/vap_phase_rf_spoiling_262112.fdl | N15: 38 | O15: =IF(_xlfn.XLOOKUP(Table1[[#This Row],[cv21 - cv_pars]],'cv_pars links'!A:A,'cv_pars links'!B:B)=0,"",_xlfn.XLOOKUP(Table1[[#This Row],[cv21 - cv_pars]],'cv_pars links'!A:A,'cv_pars links'!B:B)) -> ../waveforms/diff_cpir_2dCart4bs/diff_cpir_2dCart4bs.cvs
A16: diff_cpir_20Cart4bs2d | B16: 7.4 | C16: 1.776 | D16: 93.2 | E16: 39 | F16: =IF(_xlfn.XLOOKUP(Table1[[#This Row],[CV3 - Scan Mode]],'ak_grad links'!A:A,'ak_grad links'!B:B)=0,"",_xlfn.XLOOKUP(Table1[[#This Row],[CV3 - Scan Mode]],'ak_grad links'!A:A,'ak_grad links'!B:B)) -> diff_cpir_2dCart4bs/diffcart2D_129Xe_fov200_mtx40_nexc160_kdt52_gmax29_smax98_dur12p9_co.wav | G16: =IF(_xlfn.XLOOKUP(Table1[[#This Row],[CV3 - Scan Mode]],'recon links'!A:A,'recon links'!B:B)=0,"",_xlfn.XLOOKUP(Table1[[#This Row],[CV3 - Scan Mode]],'recon links'!A:A,'recon links'!B:B)) -> /export/home/sdc/fidall/bin/recon_diffusion.py | H16: 160 | I16: 1 | J16: =IF(_xlfn.XLOOKUP(Table1[[#This Row],[CV14 - rfpulse]],'rf links'!A:A,'rf links'!E:E)=0,"",_xlfn.XLOOKUP(Table1[[#This Row],[CV14 - rfpulse]],'rf links'!A:A,'rf links'!E:E)) -> GE soft pulse | K16: 0 | L16: 39 | M16: =IF(_xlfn.XLOOKUP(Table1[[#This Row],[CV20 - vap]],'vap links'!A:A,'vap links'!K:K)=0,"",_xlfn.XLOOKUP(Table1[[#This Row],[CV20 - vap]],'vap links'!A:A,'vap links'!K:K)) -> ../waveforms/vap_rf_spoiling/vap_phase_rf_spoiling_262112.fdl | N16: 39 | O16: =IF(_xlfn.XLOOKUP(Table1[[#This Row],[cv21 - cv_pars]],'cv_pars links'!A:A,'cv_pars links'!B:B)=0,"",_xlfn.XLOOKUP(Table1[[#This Row],[cv21 - cv_pars]],'cv_pars links'!A:A,'cv_pars links'!B:B)) -> ../waveforms/diff_cpir_2dCart4bs/diff_cpir_2dCart4bs.cvs
A17: gx_cpir_1ptDixon | B17: 20 | C17: 0.383 | D17: 7.5 | E17: 40 | F17: =IF(_xlfn.XLOOKUP(Table1[[#This Row],[CV3 - Scan Mode]],'ak_grad links'!A:A,'ak_grad links'!B:B)=0,"",_xlfn.XLOOKUP(Table1[[#This Row],[CV3 - Scan Mode]],'ak_grad links'!A:A,'ak_grad links'!B:B)) -> gx_cpir_1ptDixon/interleaved_radial3D_129xe_fov325_mtx56_intlv2002_kdt18_gmax37_smax144_dur1p6_coca_rew2_1p25_GA5.wav | G17: =IF(_xlfn.XLOOKUP(Table1[[#This Row],[CV3 - Scan Mode]],'recon links'!A:A,'recon links'!B:B)=0,"",_xlfn.XLOOKUP(Table1[[#This Row],[CV3 - Scan Mode]],'recon links'!A:A,'recon links'!B:B)) -> /export/home/sdc/fidall/bin/recon_grid3d_gx.py | H17: 2002 | I17: 40 | J17: =IF(_xlfn.XLOOKUP(Table1[[#This Row],[CV14 - rfpulse]],'rf links'!A:A,'rf links'!E:E)=0,"",_xlfn.XLOOKUP(Table1[[#This Row],[CV14 - rfpulse]],'rf links'!A:A,'rf links'!E:E)) -> rffiles/129Xe_freq_5000hz_600us_3tbw.rho | K17: 0 | L17: 40 | M17: =IF(_xlfn.XLOOKUP(Table1[[#This Row],[CV20 - vap]],'vap links'!A:A,'vap links'!K:K)=0,"",_xlfn.XLOOKUP(Table1[[#This Row],[CV20 - vap]],'vap links'!A:A,'vap links'!K:K)) -> ../waveforms/gx_cpir_1ptDixon/interleaved_radial3D_129xe_fov325_mtx56_intlv2002_kdt18_gmax37_smax144_dur1p6_coca_rew2_1p25_GA5_flip.fdl ../waveforms/gx_cpir_1ptDixon/interleaved_radial3D_129xe_fov325_mtx56_intlv2002_kdt18_gmax37_smax144_dur1p6_coca_rew2_1p25_GA5_freq.fdl ../waveforms/gx_cpir_1ptDixon/vap_phase_rf_spoiling_262112.fdl | N17: 40 | O17: =IF(_xlfn.XLOOKUP(Table1[[#This Row],[cv21 - cv_pars]],'cv_pars links'!A:A,'cv_pars links'!B:B)=0,"",_xlfn.XLOOKUP(Table1[[#This Row],[cv21 - cv_pars]],'cv_pars links'!A:A,'cv_pars links'!B:B)) -> ../waveforms/gx_cpir_1ptDixon/gx_cpir_1ptDixon.cvs | P17: try again in vivo, confirm same prescription as proton to confirm accuarate shifts
A18: anatgx_cpir_1ptDixon | B18: 10 | C18: 0.455 | D18: 2.8 | E18: 41 | F18: =IF(_xlfn.XLOOKUP(Table1[[#This Row],[CV3 - Scan Mode]],'ak_grad links'!A:A,'ak_grad links'!B:B)=0,"",_xlfn.XLOOKUP(Table1[[#This Row],[CV3 - Scan Mode]],'ak_grad links'!A:A,'ak_grad links'!B:B)) -> gx_cpir_1ptDixon/radial3D_1h_fov325_mtx56_intlv5000_kdt18_gmax19_smax141_dur1p4_coca_rew2_1p25_GA5.wav | G18: =IF(_xlfn.XLOOKUP(Table1[[#This Row],[CV3 - Scan Mode]],'recon links'!A:A,'recon links'!B:B)=0,"",_xlfn.XLOOKUP(Table1[[#This Row],[CV3 - Scan Mode]],'recon links'!A:A,'recon links'!B:B)) -> /export/home/sdc/fidall/bin/recon_grid_interp.py | H18: 5000 | I18: 0 | J18: =IF(_xlfn.XLOOKUP(Table1[[#This Row],[CV14 - rfpulse]],'rf links'!A:A,'rf links'!E:E)=0,"",_xlfn.XLOOKUP(Table1[[#This Row],[CV14 - rfpulse]],'rf links'!A:A,'rf links'!E:E)) -> GE hard pulse | K18: 0 | L18: 41 | M18: =IF(_xlfn.XLOOKUP(Table1[[#This Row],[CV20 - vap]],'vap links'!A:A,'vap links'!K:K)=0,"",_xlfn.XLOOKUP(Table1[[#This Row],[CV20 - vap]],'vap links'!A:A,'vap links'!K:K)) -> ../waveforms/gx_cpir_1ptDixon/vap_phase_rf_spoiling_262112.fdl ../waveforms/gx_cpir_1ptDixon/radial3D_1h_fov325_mtx56_intlv5000_kdt18_gmax19_smax141_dur1p4_coca_rew2_1p25_GA5_phi.fdl ../waveforms/gx_cpir_1ptDixon/radial3D_1h_fov325_mtx56_intlv5000_kdt18_gmax19_smax141_dur1p4_coca_rew2_1p25_GA5_theta.fdl | N18: 41 | O18: =IF(_xlfn.XLOOKUP(Table1[[#This Row],[cv21 - cv_pars]],'cv_pars links'!A:A,'cv_pars links'!B:B)=0,"",_xlfn.XLOOKUP(Table1[[#This Row],[cv21 - cv_pars]],'cv_pars links'!A:A,'cv_pars links'!B:B)) -> ../waveforms/gx_cpir_1ptDixon/anatgx_cpir_1ptDixon.cvs
A19: vent_cpir_floret | B19: 3.9 | C19: 0.333 | D19: 19 | E19: 42 | F19: =IF(_xlfn.XLOOKUP(Table1[[#This Row],[CV3 - Scan Mode]],'ak_grad links'!A:A,'ak_grad links'!B:B)=0,"",_xlfn.XLOOKUP(Table1[[#This Row],[CV3 - Scan Mode]],'ak_grad links'!A:A,'ak_grad links'!B:B)) -> vent_cpir_floret/floret_x005F_xe129_fov375_mtx97_arms7p1_hub3_0p4_intlv1312_bonus10_kdt8_gmax21_smax139_dur7p7_M21.wav | G19: =IF(_xlfn.XLOOKUP(Table1[[#This Row],[CV3 - Scan Mode]],'recon links'!A:A,'recon links'!B:B)=0,"",_xlfn.XLOOKUP(Table1[[#This Row],[CV3 - Scan Mode]],'recon links'!A:A,'recon links'!B:B)) -> /export/home/sdc/fidall/bin/recon_grid_interp.py | H19: 928 | I19: 0 | J19: =IF(_xlfn.XLOOKUP(Table1[[#This Row],[CV14 - rfpulse]],'rf links'!A:A,'rf links'!E:E)=0,"",_xlfn.XLOOKUP(Table1[[#This Row],[CV14 - rfpulse]],'rf links'!A:A,'rf links'!E:E)) -> GE hard pulse | K19: 0 | L19: 42 | M19: =IF(_xlfn.XLOOKUP(Table1[[#This Row],[CV20 - vap]],'vap links'!A:A,'vap links'!K:K)=0,"",_xlfn.XLOOKUP(Table1[[#This Row],[CV20 - vap]],'vap links'!A:A,'vap links'!K:K)) -> ../waveforms/vent_cpir_floret/vap_phase_rf_spoiling_262112.fdl | N19: 42 | O19: =IF(_xlfn.XLOOKUP(Table1[[#This Row],[cv21 - cv_pars]],'cv_pars links'!A:A,'cv_pars links'!B:B)=0,"",_xlfn.XLOOKUP(Table1[[#This Row],[cv21 - cv_pars]],'cv_pars links'!A:A,'cv_pars links'!B:B)) -> ../waveforms/vent_cpir_floret/vent_cpir_floret.cvs | P19: lower SNR?
A20: anatvent_cpir_floret | B20: 5 | C20: 0.333 | D20: 2.9 | E20: 43 | F20: =IF(_xlfn.XLOOKUP(Table1[[#This Row],[CV3 - Scan Mode]],'ak_grad links'!A:A,'ak_grad links'!B:B)=0,"",_xlfn.XLOOKUP(Table1[[#This Row],[CV3 - Scan Mode]],'ak_grad links'!A:A,'ak_grad links'!B:B)) -> vent_cpir_floret/floret_h1_fov375_mtx97_arms12p6_hub3_0p4_intlv2304_bonus0_kdt2_gmax21_smax148_dur1p6_M8.wav | G20: =IF(_xlfn.XLOOKUP(Table1[[#This Row],[CV3 - Scan Mode]],'recon links'!A:A,'recon links'!B:B)=0,"",_xlfn.XLOOKUP(Table1[[#This Row],[CV3 - Scan Mode]],'recon links'!A:A,'recon links'!B:B)) -> /export/home/sdc/fidall/bin/recon_grid_interp.py | H20: 2304 | I20: 0 | J20: =IF(_xlfn.XLOOKUP(Table1[[#This Row],[CV14 - rfpulse]],'rf links'!A:A,'rf links'!E:E)=0,"",_xlfn.XLOOKUP(Table1[[#This Row],[CV14 - rfpulse]],'rf links'!A:A,'rf links'!E:E)) -> GE hard pulse | K20: 0 | L20: 43 | M20: =IF(_xlfn.XLOOKUP(Table1[[#This Row],[CV20 - vap]],'vap links'!A:A,'vap links'!K:K)=0,"",_xlfn.XLOOKUP(Table1[[#This Row],[CV20 - vap]],'vap links'!A:A,'vap links'!K:K)) -> ../waveforms/vent_cpir_floret/vap_phase_rf_spoiling_262112.fdl | N20: 43 | O20: =IF(_xlfn.XLOOKUP(Table1[[#This Row],[cv21 - cv_pars]],'cv_pars links'!A:A,'cv_pars links'!B:B)=0,"",_xlfn.XLOOKUP(Table1[[#This Row],[cv21 - cv_pars]],'cv_pars links'!A:A,'cv_pars links'!B:B)) -> ../waveforms/vent_cpir_floret/vent_cpir_floret.cvs
A21: Xenon_Calibration | B21: 20 | C21: 0.383 | D21: 15 | E21: 52 | F21: =IF(_xlfn.XLOOKUP(Table1[[#This Row],[CV3 - Scan Mode]],'ak_grad links'!A:A,'ak_grad links'!B:B)=0,"",_xlfn.XLOOKUP(Table1[[#This Row],[CV3 - Scan Mode]],'ak_grad links'!A:A,'ak_grad links'!B:B)) | G21: =IF(_xlfn.XLOOKUP(Table1[[#This Row],[CV3 - Scan Mode]],'recon links'!A:A,'recon links'!B:B)=0,"",_xlfn.XLOOKUP(Table1[[#This Row],[CV3 - Scan Mode]],'recon links'!A:A,'recon links'!B:B)) -> /export/home/sdc/fidall/bin/recon_calibration_cchmc.py | H21: 520 | I21: 52 | J21: =IF(_xlfn.XLOOKUP(Table1[[#This Row],[CV14 - rfpulse]],'rf links'!A:A,'rf links'!E:E)=0,"",_xlfn.XLOOKUP(Table1[[#This Row],[CV14 - rfpulse]],'rf links'!A:A,'rf links'!E:E)) -> rffiles/129Xe_freq_5000hz_600us_3tbw.rho | K21: 0 | L21: 52 | M21: =IF(_xlfn.XLOOKUP(Table1[[#This Row],[CV20 - vap]],'vap links'!A:A,'vap links'!K:K)=0,"",_xlfn.XLOOKUP(Table1[[#This Row],[CV20 - vap]],'vap links'!A:A,'vap links'!K:K)) -> ../waveforms/cal/cal_xectc_nexc520_ndiss500_dfreq218_freq.fdl ../waveforms/cal/vap_phase_rf_spoiling_262112.fdl | N21: 52 | O21: =IF(_xlfn.XLOOKUP(Table1[[#This Row],[cv21 - cv_pars]],'cv_pars links'!A:A,'cv_pars links'!B:B)=0,"",_xlfn.XLOOKUP(Table1[[#This Row],[cv21 - cv_pars]],'cv_pars links'!A:A,'cv_pars links'!B:B)) -> ../waveforms/cal/cal_xxx.cvs | P21: validate in vivo
A22: Xenon_3D_Radial_Dixon | B22: 15 | C22: 0.383 | D22: 4.2 | E22: 53 | F22: =IF(_xlfn.XLOOKUP(Table1[[#This Row],[CV3 - Scan Mode]],'ak_grad links'!A:A,'ak_grad links'!B:B)=0,"",_xlfn.XLOOKUP(Table1[[#This Row],[CV3 - Scan Mode]],'ak_grad links'!A:A,'ak_grad links'!B:B)) -> Xenon_3D_Radial_Dixon/interleaved_radial3D_129xe_fov400_mtx64_intlv2402_kdt10_gmax31_smax106_dur1p2_coca_rew2_1p25_HAL.wav | G22: =IF(_xlfn.XLOOKUP(Table1[[#This Row],[CV3 - Scan Mode]],'recon links'!A:A,'recon links'!B:B)=0,"",_xlfn.XLOOKUP(Table1[[#This Row],[CV3 - Scan Mode]],'recon links'!A:A,'recon links'!B:B)) -> /export/home/sdc/fidall/bin/recon_grid3d_gx.py | H22: 2396 | I22: 53 | J22: =IF(_xlfn.XLOOKUP(Table1[[#This Row],[CV14 - rfpulse]],'rf links'!A:A,'rf links'!E:E)=0,"",_xlfn.XLOOKUP(Table1[[#This Row],[CV14 - rfpulse]],'rf links'!A:A,'rf links'!E:E)) -> rffiles/129Xe_freq_5000hz_600us_3tbw.rho | K22: 0 | L22: 53 | M22: =IF(_xlfn.XLOOKUP(Table1[[#This Row],[CV20 - vap]],'vap links'!A:A,'vap links'!K:K)=0,"",_xlfn.XLOOKUP(Table1[[#This Row],[CV20 - vap]],'vap links'!A:A,'vap links'!K:K)) -> ../waveforms/Xenon_3D_Radial_Dixon/interleaved_radial3D_129xe_fov400_mtx64_intlv2402_kdt10_gmax31_smax106_dur1p2_coca_rew2_1p25_HAL_flip.fdl ../waveforms/Xenon_3D_Radial_Dixon/interleaved_radial3D_129xe_fov400_mtx64_intlv2402_kdt10_gmax31_smax106_dur1p2_coca_rew2_1p25_HAL_freq.fdl ../waveforms/Xenon_3D_Radial_Dixon/vap_phase_rf_spoiling_262112.fdl | N22: 53 | O22: =IF(_xlfn.XLOOKUP(Table1[[#This Row],[cv21 - cv_pars]],'cv_pars links'!A:A,'cv_pars links'!B:B)=0,"",_xlfn.XLOOKUP(Table1[[#This Row],[cv21 - cv_pars]],'cv_pars links'!A:A,'cv_pars links'!B:B)) -> ../waveforms/Xenon_3D_Radial_Dixon/Xenon_3D_Radial_Dixon.cvs | P22: validate in vivo
A23: gx_cpir_40MRSI | B23: 16.3 | C23: 0.387 | D23: 10 | E23: 55 | F23: =IF(_xlfn.XLOOKUP(Table1[[#This Row],[CV3 - Scan Mode]],'ak_grad links'!A:A,'ak_grad links'!B:B)=0,"",_xlfn.XLOOKUP(Table1[[#This Row],[CV3 - Scan Mode]],'ak_grad links'!A:A,'ak_grad links'!B:B)) -> gx_cpir_MRSI/mrsi3D_129Xe_scheme4_3_fov400_400_320_mtx40_40_32_bw20000_npts88_nexc1437_gmax30_smax144_ncok50_10.wav | G23: =IF(_xlfn.XLOOKUP(Table1[[#This Row],[CV3 - Scan Mode]],'recon links'!A:A,'recon links'!B:B)=0,"",_xlfn.XLOOKUP(Table1[[#This Row],[CV3 - Scan Mode]],'recon links'!A:A,'recon links'!B:B)) -> /export/home/sdc/fidall/bin/recon_mrsi_xenon.py | H23: 1928 | I23: 55 | J23: =IF(_xlfn.XLOOKUP(Table1[[#This Row],[CV14 - rfpulse]],'rf links'!A:A,'rf links'!E:E)=0,"",_xlfn.XLOOKUP(Table1[[#This Row],[CV14 - rfpulse]],'rf links'!A:A,'rf links'!E:E)) -> rffiles/129Xe_freq_5000hz_600us_3tbw.rho | K23: 0 | L23: 55 | M23: =IF(_xlfn.XLOOKUP(Table1[[#This Row],[CV20 - vap]],'vap links'!A:A,'vap links'!K:K)=0,"",_xlfn.XLOOKUP(Table1[[#This Row],[CV20 - vap]],'vap links'!A:A,'vap links'!K:K)) -> ../waveforms/gx_cpir_MRSI/vap_flip_gx_16p293deg_tr10_10sat.fdl ../waveforms/gx_cpir_MRSI/vap_phase_rf_spoiling_262112.fdl | N23: 55 | O23: =IF(_xlfn.XLOOKUP(Table1[[#This Row],[cv21 - cv_pars]],'cv_pars links'!A:A,'cv_pars links'!B:B)=0,"",_xlfn.XLOOKUP(Table1[[#This Row],[cv21 - cv_pars]],'cv_pars links'!A:A,'cv_pars links'!B:B)) -> ../waveforms/gx_cpir_MRSI/gx_cpir_mrsi.cvs | P23: improve quality
A24: gx_cpir_35MRSI | B24: 16.3 | C24: 0.387 | D24: 10 | E24: 56 | F24: =IF(_xlfn.XLOOKUP(Table1[[#This Row],[CV3 - Scan Mode]],'ak_grad links'!A:A,'ak_grad links'!B:B)=0,"",_xlfn.XLOOKUP(Table1[[#This Row],[CV3 - Scan Mode]],'ak_grad links'!A:A,'ak_grad links'!B:B)) -> gx_cpir_MRSI/mrsi3D_129Xe_scheme4_3_fov350_350_280_mtx35_35_28_bw20000_npts88_nexc1264_gmax30_smax142_ncok50_10.wav | G24: =IF(_xlfn.XLOOKUP(Table1[[#This Row],[CV3 - Scan Mode]],'recon links'!A:A,'recon links'!B:B)=0,"",_xlfn.XLOOKUP(Table1[[#This Row],[CV3 - Scan Mode]],'recon links'!A:A,'recon links'!B:B)) -> /export/home/sdc/fidall/bin/recon_mrsi_xenon.py | H24: 1357 | I24: 56 | J24: =IF(_xlfn.XLOOKUP(Table1[[#This Row],[CV14 - rfpulse]],'rf links'!A:A,'rf links'!E:E)=0,"",_xlfn.XLOOKUP(Table1[[#This Row],[CV14 - rfpulse]],'rf links'!A:A,'rf links'!E:E)) -> rffiles/129Xe_freq_5000hz_600us_3tbw.rho | K24: 0 | L24: 56 | M24: =IF(_xlfn.XLOOKUP(Table1[[#This Row],[CV20 - vap]],'vap links'!A:A,'vap links'!K:K)=0,"",_xlfn.XLOOKUP(Table1[[#This Row],[CV20 - vap]],'vap links'!A:A,'vap links'!K:K)) -> ../waveforms/gx_cpir_MRSI/vap_flip_gx_16p293deg_tr10_10sat.fdl ../waveforms/gx_cpir_MRSI/vap_phase_rf_spoiling_262112.fdl | N24: 56 | O24: =IF(_xlfn.XLOOKUP(Table1[[#This Row],[cv21 - cv_pars]],'cv_pars links'!A:A,'cv_pars links'!B:B)=0,"",_xlfn.XLOOKUP(Table1[[#This Row],[cv21 - cv_pars]],'cv_pars links'!A:A,'cv_pars links'!B:B)) -> ../waveforms/gx_cpir_MRSI/gx_cpir_mrsi.cvs | P24: improve quality
A25: gx_cpir_30MRSI | B25: 16.3 | C25: 0.387 | D25: 10 | E25: 57 | F25: =IF(_xlfn.XLOOKUP(Table1[[#This Row],[CV3 - Scan Mode]],'ak_grad links'!A:A,'ak_grad links'!B:B)=0,"",_xlfn.XLOOKUP(Table1[[#This Row],[CV3 - Scan Mode]],'ak_grad links'!A:A,'ak_grad links'!B:B)) -> gx_cpir_MRSI/mrsi3D_129Xe_scheme4_3_fov300_300_240_mtx30_30_24_bw20000_npts88_nexc1047_gmax29_smax140_ncok50_10.wav | G25: =IF(_xlfn.XLOOKUP(Table1[[#This Row],[CV3 - Scan Mode]],'recon links'!A:A,'recon links'!B:B)=0,"",_xlfn.XLOOKUP(Table1[[#This Row],[CV3 - Scan Mode]],'recon links'!A:A,'recon links'!B:B)) -> /export/home/sdc/fidall/bin/recon_mrsi_xenon.py | H25: 907 | I25: 57 | J25: =IF(_xlfn.XLOOKUP(Table1[[#This Row],[CV14 - rfpulse]],'rf links'!A:A,'rf links'!E:E)=0,"",_xlfn.XLOOKUP(Table1[[#This Row],[CV14 - rfpulse]],'rf links'!A:A,'rf links'!E:E)) -> rffiles/129Xe_freq_5000hz_600us_3tbw.rho | K25: 0 | L25: 57 | M25: =IF(_xlfn.XLOOKUP(Table1[[#This Row],[CV20 - vap]],'vap links'!A:A,'vap links'!K:K)=0,"",_xlfn.XLOOKUP(Table1[[#This Row],[CV20 - vap]],'vap links'!A:A,'vap links'!K:K)) -> ../waveforms/gx_cpir_MRSI/vap_flip_gx_16p293deg_tr10_10sat.fdl ../waveforms/gx_cpir_MRSI/vap_phase_rf_spoiling_262112.fdl | N25: 57 | O25: =IF(_xlfn.XLOOKUP(Table1[[#This Row],[cv21 - cv_pars]],'cv_pars links'!A:A,'cv_pars links'!B:B)=0,"",_xlfn.XLOOKUP(Table1[[#This Row],[cv21 - cv_pars]],'cv_pars links'!A:A,'cv_pars links'!B:B)) -> ../waveforms/gx_cpir_MRSI/gx_cpir_mrsi.cvs | P25: improve quality
A26: gx_cpir_25MRSI | B26: 16.3 | C26: 0.387 | D26: 10 | E26: 58 | F26: =IF(_xlfn.XLOOKUP(Table1[[#This Row],[CV3 - Scan Mode]],'ak_grad links'!A:A,'ak_grad links'!B:B)=0,"",_xlfn.XLOOKUP(Table1[[#This Row],[CV3 - Scan Mode]],'ak_grad links'!A:A,'ak_grad links'!B:B)) -> gx_cpir_MRSI/mrsi3D_129Xe_scheme4_3_fov250_250_200_mtx25_25_20_bw20000_npts88_nexc835_gmax30_smax140_ncok50_10.wav | G26: =IF(_xlfn.XLOOKUP(Table1[[#This Row],[CV3 - Scan Mode]],'recon links'!A:A,'recon links'!B:B)=0,"",_xlfn.XLOOKUP(Table1[[#This Row],[CV3 - Scan Mode]],'recon links'!A:A,'recon links'!B:B)) -> /export/home/sdc/fidall/bin/recon_mrsi_xenon.py | H26: 578 | I26: 58 | J26: =IF(_xlfn.XLOOKUP(Table1[[#This Row],[CV14 - rfpulse]],'rf links'!A:A,'rf links'!E:E)=0,"",_xlfn.XLOOKUP(Table1[[#This Row],[CV14 - rfpulse]],'rf links'!A:A,'rf links'!E:E)) -> rffiles/129Xe_freq_5000hz_600us_3tbw.rho | K26: 0 | L26: 58 | M26: =IF(_xlfn.XLOOKUP(Table1[[#This Row],[CV20 - vap]],'vap links'!A:A,'vap links'!K:K)=0,"",_xlfn.XLOOKUP(Table1[[#This Row],[CV20 - vap]],'vap links'!A:A,'vap links'!K:K)) -> ../waveforms/gx_cpir_MRSI/vap_flip_gx_16p293deg_tr10_10sat.fdl ../waveforms/gx_cpir_MRSI/vap_phase_rf_spoiling_262112.fdl | N26: 58 | O26: =IF(_xlfn.XLOOKUP(Table1[[#This Row],[cv21 - cv_pars]],'cv_pars links'!A:A,'cv_pars links'!B:B)=0,"",_xlfn.XLOOKUP(Table1[[#This Row],[cv21 - cv_pars]],'cv_pars links'!A:A,'cv_pars links'!B:B)) -> ../waveforms/gx_cpir_MRSI/gx_cpir_mrsi.cvs | P26: improve quality
A27: gx_XeCTC_1ptDixon | B27: 20 | C27: 0.383 | D27: 7.5 | E27: 66 | F27: =IF(_xlfn.XLOOKUP(Table1[[#This Row],[CV3 - Scan Mode]],'ak_grad links'!A:A,'ak_grad links'!B:B)=0,"",_xlfn.XLOOKUP(Table1[[#This Row],[CV3 - Scan Mode]],'ak_grad links'!A:A,'ak_grad links'!B:B)) -> gx_XeCTC_1ptDixon/interleaved_radial3D_129xe_fov400_mtx64_intlv2002_kdt10_gmax31_smax106_dur1p2_coca_rew2_1p25_HAL.wav | G27: =IF(_xlfn.XLOOKUP(Table1[[#This Row],[CV3 - Scan Mode]],'recon links'!A:A,'recon links'!B:B)=0,"",_xlfn.XLOOKUP(Table1[[#This Row],[CV3 - Scan Mode]],'recon links'!A:A,'recon links'!B:B)) -> /export/home/sdc/fidall/bin/recon_grid3d_gx.py | H27: 2002 | I27: 66 | J27: =IF(_xlfn.XLOOKUP(Table1[[#This Row],[CV14 - rfpulse]],'rf links'!A:A,'rf links'!E:E)=0,"",_xlfn.XLOOKUP(Table1[[#This Row],[CV14 - rfpulse]],'rf links'!A:A,'rf links'!E:E)) -> rffiles/129Xe_freq_5000hz_600us_3tbw.rho | K27: 0 | L27: 66 | M27: =IF(_xlfn.XLOOKUP(Table1[[#This Row],[CV20 - vap]],'vap links'!A:A,'vap links'!K:K)=0,"",_xlfn.XLOOKUP(Table1[[#This Row],[CV20 - vap]],'vap links'!A:A,'vap links'!K:K)) -> ../waveforms/gx_XeCTC_1ptDixon/interleaved_radial3D_129xe_fov400_mtx64_intlv2002_kdt10_gmax31_smax106_dur1p2_coca_rew2_1p25_HAL_flip.fdl ../waveforms/gx_XeCTC_1ptDixon/interleaved_radial3D_129xe_fov400_mtx64_intlv2002_kdt10_gmax31_smax106_dur1p2_coca_rew2_1p25_HAL_freq.fdl ../waveforms/gx_XeCTC_1ptDixon/vap_phase_rf_spoiling_262112.fdl | N27: 66 | O27: =IF(_xlfn.XLOOKUP(Table1[[#This Row],[cv21 - cv_pars]],'cv_pars links'!A:A,'cv_pars links'!B:B)=0,"",_xlfn.XLOOKUP(Table1[[#This Row],[cv21 - cv_pars]],'cv_pars links'!A:A,'cv_pars links'!B:B)) -> ../waveforms/gx_XeCTC_1ptDixon/gx_xectc_1ptDixon.cvs | P27: validate in vivo
A28: anatgx_XeCTC_1ptDixon | B28: 10 | C28: 0.455 | D28: 3.4 | E28: 67 | F28: =IF(_xlfn.XLOOKUP(Table1[[#This Row],[CV3 - Scan Mode]],'ak_grad links'!A:A,'ak_grad links'!B:B)=0,"",_xlfn.XLOOKUP(Table1[[#This Row],[CV3 - Scan Mode]],'ak_grad links'!A:A,'ak_grad links'!B:B)) -> gx_XeCTC_1ptDixon/radial3D_1h_fov400_mtx64_intlv4600_kdt18_gmax6_smax17_dur2_coca_rew2_1p25_HAL.wav | G28: =IF(_xlfn.XLOOKUP(Table1[[#This Row],[CV3 - Scan Mode]],'recon links'!A:A,'recon links'!B:B)=0,"",_xlfn.XLOOKUP(Table1[[#This Row],[CV3 - Scan Mode]],'recon links'!A:A,'recon links'!B:B)) -> /export/home/sdc/fidall/bin/recon_grid_interp.py | H28: 4600 | I28: 0 | J28: =IF(_xlfn.XLOOKUP(Table1[[#This Row],[CV14 - rfpulse]],'rf links'!A:A,'rf links'!E:E)=0,"",_xlfn.XLOOKUP(Table1[[#This Row],[CV14 - rfpulse]],'rf links'!A:A,'rf links'!E:E)) -> GE hard pulse | K28: 0 | L28: 67 | M28: =IF(_xlfn.XLOOKUP(Table1[[#This Row],[CV20 - vap]],'vap links'!A:A,'vap links'!K:K)=0,"",_xlfn.XLOOKUP(Table1[[#This Row],[CV20 - vap]],'vap links'!A:A,'vap links'!K:K)) -> ../waveforms/gx_XeCTC_1ptDixon/vap_phase_rf_spoiling_262112.fdl ../waveforms/gx_XeCTC_1ptDixon/radial3D_1h_fov400_mtx64_intlv4600_kdt18_gmax6_smax17_dur2_coca_rew2_1p25_HAL_phi.fdl ../waveforms/gx_XeCTC_1ptDixon/radial3D_1h_fov400_mtx64_intlv4600_kdt18_gmax6_smax17_dur2_coca_rew2_1p25_HAL_theta.fdl | N28: 67 | O28: =IF(_xlfn.XLOOKUP(Table1[[#This Row],[cv21 - cv_pars]],'cv_pars links'!A:A,'cv_pars links'!B:B)=0,"",_xlfn.XLOOKUP(Table1[[#This Row],[cv21 - cv_pars]],'cv_pars links'!A:A,'cv_pars links'!B:B)) -> ../waveforms/gx_XeCTC_1ptDixon/anatgx_XeCTC_1ptDixon.cvs
A29: qa_cpir_nutation | B29: 180 | C29: 0 | D29: 2500 | E29: 68 | F29: =IF(_xlfn.XLOOKUP(Table1[[#This Row],[CV3 - Scan Mode]],'ak_grad links'!A:A,'ak_grad links'!B:B)=0,"",_xlfn.XLOOKUP(Table1[[#This Row],[CV3 - Scan Mode]],'ak_grad links'!A:A,'ak_grad links'!B:B)) | G29: =IF(_xlfn.XLOOKUP(Table1[[#This Row],[CV3 - Scan Mode]],'recon links'!A:A,'recon links'!B:B)=0,"",_xlfn.XLOOKUP(Table1[[#This Row],[CV3 - Scan Mode]],'recon links'!A:A,'recon links'!B:B)) -> /export/home/sdc/fidall/bin/recon_nutation.py | H29: 18 | I29: 7 | J29: =IF(_xlfn.XLOOKUP(Table1[[#This Row],[CV14 - rfpulse]],'rf links'!A:A,'rf links'!E:E)=0,"",_xlfn.XLOOKUP(Table1[[#This Row],[CV14 - rfpulse]],'rf links'!A:A,'rf links'!E:E)) | K29: 0 | L29: 68 | M29: =IF(_xlfn.XLOOKUP(Table1[[#This Row],[CV20 - vap]],'vap links'!A:A,'vap links'!K:K)=0,"",_xlfn.XLOOKUP(Table1[[#This Row],[CV20 - vap]],'vap links'!A:A,'vap links'!K:K)) -> ../waveforms/qa_cpir_nutation/qa_cpir_nutation_nexc18_start10_end180_flip.fdl | N29: 68 | O29: =IF(_xlfn.XLOOKUP(Table1[[#This Row],[cv21 - cv_pars]],'cv_pars links'!A:A,'cv_pars links'!B:B)=0,"",_xlfn.XLOOKUP(Table1[[#This Row],[cv21 - cv_pars]],'cv_pars links'!A:A,'cv_pars links'!B:B)) -> ../waveforms/qa_cpir_nutation/qa_cpir_nutation.cvs
A30: vent_cpir_40SpiralVD2d | B30: 20.2 | C30: 2.048 | D30: 188.2 | E30: 70 | F30: =IF(_xlfn.XLOOKUP(Table1[[#This Row],[CV3 - Scan Mode]],'ak_grad links'!A:A,'ak_grad links'!B:B)=0,"",_xlfn.XLOOKUP(Table1[[#This Row],[CV3 - Scan Mode]],'ak_grad links'!A:A,'ak_grad links'!B:B)) -> vent_cpir_2dSpiralVD/spiralbni_129xe_fov400_mtx134_nexc26_bonus2_vd2start0p5stop1r2_kdt4_gmax41_smax119_dur6p9_M4.wav | G30: =IF(_xlfn.XLOOKUP(Table1[[#This Row],[CV3 - Scan Mode]],'recon links'!A:A,'recon links'!B:B)=0,"",_xlfn.XLOOKUP(Table1[[#This Row],[CV3 - Scan Mode]],'recon links'!A:A,'recon links'!B:B)) -> /export/home/sdc/fidall/bin/recon_grid_interp.py | H30: 26 | I30: 1 | J30: =IF(_xlfn.XLOOKUP(Table1[[#This Row],[CV14 - rfpulse]],'rf links'!A:A,'rf links'!E:E)=0,"",_xlfn.XLOOKUP(Table1[[#This Row],[CV14 - rfpulse]],'rf links'!A:A,'rf links'!E:E)) -> GE soft pulse | K30: 0 | L30: 70 | M30: =IF(_xlfn.XLOOKUP(Table1[[#This Row],[CV20 - vap]],'vap links'!A:A,'vap links'!K:K)=0,"",_xlfn.XLOOKUP(Table1[[#This Row],[CV20 - vap]],'vap links'!A:A,'vap links'!K:K)) -> ../waveforms/vent_cpir_2dSpiralVD/vap_phase_rf_spoiling_262112.fdl | N30: 70 | O30: =IF(_xlfn.XLOOKUP(Table1[[#This Row],[cv21 - cv_pars]],'cv_pars links'!A:A,'cv_pars links'!B:B)=0,"",_xlfn.XLOOKUP(Table1[[#This Row],[cv21 - cv_pars]],'cv_pars links'!A:A,'cv_pars links'!B:B)) -> ../waveforms/vent_cpir_2dSpiralVD/vent_cpir_2dSpiralVD.cvs
A31: vent_cpir_35SpiralVD2d | B31: 20.2 | C31: 2.048 | D31: 191.7 | E31: 71 | F31: =IF(_xlfn.XLOOKUP(Table1[[#This Row],[CV3 - Scan Mode]],'ak_grad links'!A:A,'ak_grad links'!B:B)=0,"",_xlfn.XLOOKUP(Table1[[#This Row],[CV3 - Scan Mode]],'ak_grad links'!A:A,'ak_grad links'!B:B)) -> vent_cpir_2dSpiralVD/spiralbni_129xe_fov350_mtx117_nexc22_bonus2_vd2start0p5stop1r2_kdt4_gmax41_smax119_dur7p2_M4.wav | G31: =IF(_xlfn.XLOOKUP(Table1[[#This Row],[CV3 - Scan Mode]],'recon links'!A:A,'recon links'!B:B)=0,"",_xlfn.XLOOKUP(Table1[[#This Row],[CV3 - Scan Mode]],'recon links'!A:A,'recon links'!B:B)) -> /export/home/sdc/fidall/bin/recon_grid_interp.py | H31: 22 | I31: 1 | J31: =IF(_xlfn.XLOOKUP(Table1[[#This Row],[CV14 - rfpulse]],'rf links'!A:A,'rf links'!E:E)=0,"",_xlfn.XLOOKUP(Table1[[#This Row],[CV14 - rfpulse]],'rf links'!A:A,'rf links'!E:E)) -> GE soft pulse | K31: 0 | L31: 71 | M31: =IF(_xlfn.XLOOKUP(Table1[[#This Row],[CV20 - vap]],'vap links'!A:A,'vap links'!K:K)=0,"",_xlfn.XLOOKUP(Table1[[#This Row],[CV20 - vap]],'vap links'!A:A,'vap links'!K:K)) -> ../waveforms/vent_cpir_2dSpiralVD/vap_phase_rf_spoiling_262112.fdl | N31: 71 | O31: =IF(_xlfn.XLOOKUP(Table1[[#This Row],[cv21 - cv_pars]],'cv_pars links'!A:A,'cv_pars links'!B:B)=0,"",_xlfn.XLOOKUP(Table1[[#This Row],[cv21 - cv_pars]],'cv_pars links'!A:A,'cv_pars links'!B:B)) -> ../waveforms/vent_cpir_2dSpiralVD/vent_cpir_2dSpiralVD.cvs
A32: vent_cpir_30SpiralVD2d | B32: 21.3 | C32: 2.048 | D32: 173.1 | E32: 72 | F32: =IF(_xlfn.XLOOKUP(Table1[[#This Row],[CV3 - Scan Mode]],'ak_grad links'!A:A,'ak_grad links'!B:B)=0,"",_xlfn.XLOOKUP(Table1[[#This Row],[CV3 - Scan Mode]],'ak_grad links'!A:A,'ak_grad links'!B:B)) -> vent_cpir_2dSpiralVD/spiralbni_129xe_fov300_mtx100_nexc20_bonus2_vd2start0p5stop1r2_kdt4_gmax41_smax119_dur6p8_M4.wav | G32: =IF(_xlfn.XLOOKUP(Table1[[#This Row],[CV3 - Scan Mode]],'recon links'!A:A,'recon links'!B:B)=0,"",_xlfn.XLOOKUP(Table1[[#This Row],[CV3 - Scan Mode]],'recon links'!A:A,'recon links'!B:B)) -> /export/home/sdc/fidall/bin/recon_grid_interp.py | H32: 20 | I32: 1 | J32: =IF(_xlfn.XLOOKUP(Table1[[#This Row],[CV14 - rfpulse]],'rf links'!A:A,'rf links'!E:E)=0,"",_xlfn.XLOOKUP(Table1[[#This Row],[CV14 - rfpulse]],'rf links'!A:A,'rf links'!E:E)) -> GE soft pulse | K32: 0 | L32: 72 | M32: =IF(_xlfn.XLOOKUP(Table1[[#This Row],[CV20 - vap]],'vap links'!A:A,'vap links'!K:K)=0,"",_xlfn.XLOOKUP(Table1[[#This Row],[CV20 - vap]],'vap links'!A:A,'vap links'!K:K)) -> ../waveforms/vent_cpir_2dSpiralVD/vap_phase_rf_spoiling_262112.fdl | N32: 72 | O32: =IF(_xlfn.XLOOKUP(Table1[[#This Row],[cv21 - cv_pars]],'cv_pars links'!A:A,'cv_pars links'!B:B)=0,"",_xlfn.XLOOKUP(Table1[[#This Row],[cv21 - cv_pars]],'cv_pars links'!A:A,'cv_pars links'!B:B)) -> ../waveforms/vent_cpir_2dSpiralVD/vent_cpir_2dSpiralVD.cvs
A33: vent_cpir_25SpiralVD2d | B33: 24 | C33: 2.048 | D33: 155.1 | E33: 73 | F33: =IF(_xlfn.XLOOKUP(Table1[[#This Row],[CV3 - Scan Mode]],'ak_grad links'!A:A,'ak_grad links'!B:B)=0,"",_xlfn.XLOOKUP(Table1[[#This Row],[CV3 - Scan Mode]],'ak_grad links'!A:A,'ak_grad links'!B:B)) -> vent_cpir_2dSpiralVD/spiralbni_129xe_fov250_mtx84_nexc18_bonus2_vd2start0p5stop1r2_kdt4_gmax41_smax119_dur6p5_M4.wav | G33: =IF(_xlfn.XLOOKUP(Table1[[#This Row],[CV3 - Scan Mode]],'recon links'!A:A,'recon links'!B:B)=0,"",_xlfn.XLOOKUP(Table1[[#This Row],[CV3 - Scan Mode]],'recon links'!A:A,'recon links'!B:B)) -> /export/home/sdc/fidall/bin/recon_grid_interp.py | H33: 18 | I33: 1 | J33: =IF(_xlfn.XLOOKUP(Table1[[#This Row],[CV14 - rfpulse]],'rf links'!A:A,'rf links'!E:E)=0,"",_xlfn.XLOOKUP(Table1[[#This Row],[CV14 - rfpulse]],'rf links'!A:A,'rf links'!E:E)) -> GE soft pulse | K33: 0 | L33: 73 | M33: =IF(_xlfn.XLOOKUP(Table1[[#This Row],[CV20 - vap]],'vap links'!A:A,'vap links'!K:K)=0,"",_xlfn.XLOOKUP(Table1[[#This Row],[CV20 - vap]],'vap links'!A:A,'vap links'!K:K)) -> ../waveforms/vent_cpir_2dSpiralVD/vap_phase_rf_spoiling_262112.fdl | N33: 73 | O33: =IF(_xlfn.XLOOKUP(Table1[[#This Row],[cv21 - cv_pars]],'cv_pars links'!A:A,'cv_pars links'!B:B)=0,"",_xlfn.XLOOKUP(Table1[[#This Row],[cv21 - cv_pars]],'cv_pars links'!A:A,'cv_pars links'!B:B)) -> ../waveforms/vent_cpir_2dSpiralVD/vent_cpir_2dSpiralVD.cvs
A34: vent_cpir_20SpiralVD2d | B34: 25.9 | C34: 2.048 | D34: 159.9 | E34: 74 | F34: =IF(_xlfn.XLOOKUP(Table1[[#This Row],[CV3 - Scan Mode]],'ak_grad links'!A:A,'ak_grad links'!B:B)=0,"",_xlfn.XLOOKUP(Table1[[#This Row],[CV3 - Scan Mode]],'ak_grad links'!A:A,'ak_grad links'!B:B)) -> vent_cpir_2dSpiralVD/spiralbni_129xe_fov200_mtx67_nexc14_bonus2_vd2start0p5stop1r2_kdt8_gmax41_smax119_dur6p9_M4.wav | G34: =IF(_xlfn.XLOOKUP(Table1[[#This Row],[CV3 - Scan Mode]],'recon links'!A:A,'recon links'!B:B)=0,"",_xlfn.XLOOKUP(Table1[[#This Row],[CV3 - Scan Mode]],'recon links'!A:A,'recon links'!B:B)) -> /export/home/sdc/fidall/bin/recon_grid_interp.py | H34: 14 | I34: 1 | J34: =IF(_xlfn.XLOOKUP(Table1[[#This Row],[CV14 - rfpulse]],'rf links'!A:A,'rf links'!E:E)=0,"",_xlfn.XLOOKUP(Table1[[#This Row],[CV14 - rfpulse]],'rf links'!A:A,'rf links'!E:E)) -> GE soft pulse | K34: 0 | L34: 74 | M34: =IF(_xlfn.XLOOKUP(Table1[[#This Row],[CV20 - vap]],'vap links'!A:A,'vap links'!K:K)=0,"",_xlfn.XLOOKUP(Table1[[#This Row],[CV20 - vap]],'vap links'!A:A,'vap links'!K:K)) -> ../waveforms/vent_cpir_2dSpiralVD/vap_phase_rf_spoiling_262112.fdl | N34: 74 | O34: =IF(_xlfn.XLOOKUP(Table1[[#This Row],[cv21 - cv_pars]],'cv_pars links'!A:A,'cv_pars links'!B:B)=0,"",_xlfn.XLOOKUP(Table1[[#This Row],[cv21 - cv_pars]],'cv_pars links'!A:A,'cv_pars links'!B:B)) -> ../waveforms/vent_cpir_2dSpiralVD/vent_cpir_2dSpiralVD.cvs
A35: anatvent_cpir_40SpiralVD2d | B35: 10 | C35: 1.204 | D35: 111.7 | E35: 75 | F35: =IF(_xlfn.XLOOKUP(Table1[[#This Row],[CV3 - Scan Mode]],'ak_grad links'!A:A,'ak_grad links'!B:B)=0,"",_xlfn.XLOOKUP(Table1[[#This Row],[CV3 - Scan Mode]],'ak_grad links'!A:A,'ak_grad links'!B:B)) -> vent_cpir_2dSpiralVD/spiralbni_1h_fov400_mtx134_nexc24_bonus0_vd0start0stop1r1_kdt2_gmax24_smax149_dur2p1_M4.wav | G35: =IF(_xlfn.XLOOKUP(Table1[[#This Row],[CV3 - Scan Mode]],'recon links'!A:A,'recon links'!B:B)=0,"",_xlfn.XLOOKUP(Table1[[#This Row],[CV3 - Scan Mode]],'recon links'!A:A,'recon links'!B:B)) -> /export/home/sdc/fidall/bin/recon_grid_interp.py | H35: 24 | I35: 1 | J35: =IF(_xlfn.XLOOKUP(Table1[[#This Row],[CV14 - rfpulse]],'rf links'!A:A,'rf links'!E:E)=0,"",_xlfn.XLOOKUP(Table1[[#This Row],[CV14 - rfpulse]],'rf links'!A:A,'rf links'!E:E)) -> GE soft pulse | K35: 0 | L35: 75 | M35: =IF(_xlfn.XLOOKUP(Table1[[#This Row],[CV20 - vap]],'vap links'!A:A,'vap links'!K:K)=0,"",_xlfn.XLOOKUP(Table1[[#This Row],[CV20 - vap]],'vap links'!A:A,'vap links'!K:K)) -> ../waveforms/vent_cpir_2dSpiralVD/vap_phase_rf_spoiling_262112.fdl | N35: 75 | O35: =IF(_xlfn.XLOOKUP(Table1[[#This Row],[cv21 - cv_pars]],'cv_pars links'!A:A,'cv_pars links'!B:B)=0,"",_xlfn.XLOOKUP(Table1[[#This Row],[cv21 - cv_pars]],'cv_pars links'!A:A,'cv_pars links'!B:B)) -> ../waveforms/vent_cpir_2dSpiralVD/vent_cpir_2dSpiralVD.cvs
A36: anatvent_cpir_35SpiralVD2d | B36: 10 | C36: 1.204 | D36: 104.3 | E36: 76 | F36: =IF(_xlfn.XLOOKUP(Table1[[#This Row],[CV3 - Scan Mode]],'ak_grad links'!A:A,'ak_grad links'!B:B)=0,"",_xlfn.XLOOKUP(Table1[[#This Row],[CV3 - Scan Mode]],'ak_grad links'!A:A,'ak_grad links'!B:B)) -> vent_cpir_2dSpiralVD/spiralbni_1h_fov350_mtx117_nexc21_bonus0_vd0start0stop1r1_kdt2_gmax24_smax149_dur2p1_M4.wav | G36: =IF(_xlfn.XLOOKUP(Table1[[#This Row],[CV3 - Scan Mode]],'recon links'!A:A,'recon links'!B:B)=0,"",_xlfn.XLOOKUP(Table1[[#This Row],[CV3 - Scan Mode]],'recon links'!A:A,'recon links'!B:B)) -> /export/home/sdc/fidall/bin/recon_grid_interp.py | H36: 21 | I36: 1 | J36: =IF(_xlfn.XLOOKUP(Table1[[#This Row],[CV14 - rfpulse]],'rf links'!A:A,'rf links'!E:E)=0,"",_xlfn.XLOOKUP(Table1[[#This Row],[CV14 - rfpulse]],'rf links'!A:A,'rf links'!E:E)) -> GE soft pulse | K36: 0 | L36: 76 | M36: =IF(_xlfn.XLOOKUP(Table1[[#This Row],[CV20 - vap]],'vap links'!A:A,'vap links'!K:K)=0,"",_xlfn.XLOOKUP(Table1[[#This Row],[CV20 - vap]],'vap links'!A:A,'vap links'!K:K)) -> ../waveforms/vent_cpir_2dSpiralVD/vap_phase_rf_spoiling_262112.fdl | N36: 76 | O36: =IF(_xlfn.XLOOKUP(Table1[[#This Row],[cv21 - cv_pars]],'cv_pars links'!A:A,'cv_pars links'!B:B)=0,"",_xlfn.XLOOKUP(Table1[[#This Row],[cv21 - cv_pars]],'cv_pars links'!A:A,'cv_pars links'!B:B)) -> ../waveforms/vent_cpir_2dSpiralVD/vent_cpir_2dSpiralVD.cvs
A37: anatvent_cpir_30SpiralVD2d | B37: 10 | C37: 1.204 | D37: 96.8 | E37: 77 | F37: =IF(_xlfn.XLOOKUP(Table1[[#This Row],[CV3 - Scan Mode]],'ak_grad links'!A:A,'ak_grad links'!B:B)=0,"",_xlfn.XLOOKUP(Table1[[#This Row],[CV3 - Scan Mode]],'ak_grad links'!A:A,'ak_grad links'!B:B)) -> vent_cpir_2dSpiralVD/spiralbni_1h_fov300_mtx100_nexc18_bonus0_vd0start0stop1r1_kdt2_gmax24_smax149_dur2p1_M4.wav | G37: =IF(_xlfn.XLOOKUP(Table1[[#This Row],[CV3 - Scan Mode]],'recon links'!A:A,'recon links'!B:B)=0,"",_xlfn.XLOOKUP(Table1[[#This Row],[CV3 - Scan Mode]],'recon links'!A:A,'recon links'!B:B)) -> /export/home/sdc/fidall/bin/recon_grid_interp.py | H37: 18 | I37: 1 | J37: =IF(_xlfn.XLOOKUP(Table1[[#This Row],[CV14 - rfpulse]],'rf links'!A:A,'rf links'!E:E)=0,"",_xlfn.XLOOKUP(Table1[[#This Row],[CV14 - rfpulse]],'rf links'!A:A,'rf links'!E:E)) -> GE soft pulse | K37: 0 | L37: 77 | M37: =IF(_xlfn.XLOOKUP(Table1[[#This Row],[CV20 - vap]],'vap links'!A:A,'vap links'!K:K)=0,"",_xlfn.XLOOKUP(Table1[[#This Row],[CV20 - vap]],'vap links'!A:A,'vap links'!K:K)) -> ../waveforms/vent_cpir_2dSpiralVD/vap_phase_rf_spoiling_262112.fdl | N37: 77 | O37: =IF(_xlfn.XLOOKUP(Table1[[#This Row],[cv21 - cv_pars]],'cv_pars links'!A:A,'cv_pars links'!B:B)=0,"",_xlfn.XLOOKUP(Table1[[#This Row],[cv21 - cv_pars]],'cv_pars links'!A:A,'cv_pars links'!B:B)) -> ../waveforms/vent_cpir_2dSpiralVD/vent_cpir_2dSpiralVD.cvs
A38: anatvent_cpir_25SpiralVD2d | B38: 10 | C38: 1.204 | D38: 89.4 | E38: 78 | F38: =IF(_xlfn.XLOOKUP(Table1[[#This Row],[CV3 - Scan Mode]],'ak_grad links'!A:A,'ak_grad links'!B:B)=0,"",_xlfn.XLOOKUP(Table1[[#This Row],[CV3 - Scan Mode]],'ak_grad links'!A:A,'ak_grad links'!B:B)) -> vent_cpir_2dSpiralVD/spiralbni_1h_fov250_mtx84_nexc15_bonus0_vd0start0stop1r1_kdt2_gmax24_smax149_dur2p1_M4.wav | G38: =IF(_xlfn.XLOOKUP(Table1[[#This Row],[CV3 - Scan Mode]],'recon links'!A:A,'recon links'!B:B)=0,"",_xlfn.XLOOKUP(Table1[[#This Row],[CV3 - Scan Mode]],'recon links'!A:A,'recon links'!B:B)) -> /export/home/sdc/fidall/bin/recon_grid_interp.py | H38: 15 | I38: 1 | J38: =IF(_xlfn.XLOOKUP(Table1[[#This Row],[CV14 - rfpulse]],'rf links'!A:A,'rf links'!E:E)=0,"",_xlfn.XLOOKUP(Table1[[#This Row],[CV14 - rfpulse]],'rf links'!A:A,'rf links'!E:E)) -> GE soft pulse | K38: 0 | L38: 78 | M38: =IF(_xlfn.XLOOKUP(Table1[[#This Row],[CV20 - vap]],'vap links'!A:A,'vap links'!K:K)=0,"",_xlfn.XLOOKUP(Table1[[#This Row],[CV20 - vap]],'vap links'!A:A,'vap links'!K:K)) -> ../waveforms/vent_cpir_2dSpiralVD/vap_phase_rf_spoiling_262112.fdl | N38: 78 | O38: =IF(_xlfn.XLOOKUP(Table1[[#This Row],[cv21 - cv_pars]],'cv_pars links'!A:A,'cv_pars links'!B:B)=0,"",_xlfn.XLOOKUP(Table1[[#This Row],[cv21 - cv_pars]],'cv_pars links'!A:A,'cv_pars links'!B:B)) -> ../waveforms/vent_cpir_2dSpiralVD/vent_cpir_2dSpiralVD.cvs
A39: anatvent_cpir_20SpiralVD2d | B39: 10 | C39: 1.204 | D39: 89.5 | E39: 79 | F39: =IF(_xlfn.XLOOKUP(Table1[[#This Row],[CV3 - Scan Mode]],'ak_grad links'!A:A,'ak_grad links'!B:B)=0,"",_xlfn.XLOOKUP(Table1[[#This Row],[CV3 - Scan Mode]],'ak_grad links'!A:A,'ak_grad links'!B:B)) -> vent_cpir_2dSpiralVD/spiralbni_1h_fov200_mtx67_nexc12_bonus0_vd0start0stop1r1_kdt4_gmax24_smax149_dur2p1_M4.wav | G39: =IF(_xlfn.XLOOKUP(Table1[[#This Row],[CV3 - Scan Mode]],'recon links'!A:A,'recon links'!B:B)=0,"",_xlfn.XLOOKUP(Table1[[#This Row],[CV3 - Scan Mode]],'recon links'!A:A,'recon links'!B:B)) -> /export/home/sdc/fidall/bin/recon_grid_interp.py | H39: 12 | I39: 1 | J39: =IF(_xlfn.XLOOKUP(Table1[[#This Row],[CV14 - rfpulse]],'rf links'!A:A,'rf links'!E:E)=0,"",_xlfn.XLOOKUP(Table1[[#This Row],[CV14 - rfpulse]],'rf links'!A:A,'rf links'!E:E)) -> GE soft pulse | K39: 0 | L39: 79 | M39: =IF(_xlfn.XLOOKUP(Table1[[#This Row],[CV20 - vap]],'vap links'!A:A,'vap links'!K:K)=0,"",_xlfn.XLOOKUP(Table1[[#This Row],[CV20 - vap]],'vap links'!A:A,'vap links'!K:K)) -> ../waveforms/vent_cpir_2dSpiralVD/vap_phase_rf_spoiling_262112.fdl | N39: 79 | O39: =IF(_xlfn.XLOOKUP(Table1[[#This Row],[cv21 - cv_pars]],'cv_pars links'!A:A,'cv_pars links'!B:B)=0,"",_xlfn.XLOOKUP(Table1[[#This Row],[cv21 - cv_pars]],'cv_pars links'!A:A,'cv_pars links'!B:B)) -> ../waveforms/vent_cpir_2dSpiralVD/vent_cpir_2dSpiralVD.cvs

Sheet ak_grad links
A1: Link # | B1: ak_grad
A2: 1 | B2: MRSI Mode
A3: 2 | B3: spiral/spiral_13C_fov80_mtx28_arms1_kdt24_gmax33_smax119_dur24p6.wav
A4: 3 | B4: spiral/spiral_13C_fov120_mtx34_arms1_kdt16_gmax33_smax119_dur25p3.wav
A5: 4 | B5: spiral/spiral_13C_fov200_mtx42_arms1_kdt8_gmax33_smax119_dur25p7.wav
A6: 5 | B6: spiral/spiral_13C_fov300_mtx48_arms1_kdt8_gmax30_smax119_dur25p5.wav
A7: 6 | B7: spiral/spiral_13C_fov400_mtx52_arms1_kdt8_gmax27_smax119_dur24p9.wav
A8: 7 | B8: spiral/spiral_1H_fov200_mtx50_arms1_kdt2_gmax19_smax119_dur16p6.wav
A9: 8 | B9: spiral/spiral_1H_fov200_mtx200_arms50_kdt2_gmax29_smax119_dur3p3.wav
A10: 9 | B10: spiral/spiral_1H_fov400_mtx100_arms4_kdt2_gmax15_smax119_dur9.wav
A11: 10 | B11: mrp/radial2D_1H_fov200_mtx300_intlv1000_kdt4_gmax25_smax100_dur4p5_fsca_rew1_GA7.wav
A12: 11 | B12: mrp/radial4D_1H_fov200_53_mtx300_20_intlv40000_kdt4_gmax25_smax100_dur4p5_fsca_rew1_GA7_zPE3.wav
A13: 12
A14: 13
A15: 14
A16: 15 | B16: cart/cart2D_129Xe_fov300x240_mtx100x80_nexc80_kdt20_gmax32_smax99_dur4p92.wav
A17: 16 | B17: cart/cart3D_129Xe_fov300x240x144_mtx100x80x24_nexc1928_kdt20_gmax33_smax92_dur5p76_bal_co.wav
A18: 17 | B18: mrsi/mrsi3D_129Xe_scheme2_3_fov270_240_150_mtx18_16_10_bw20000_npts88_nexc1586_gmax16_smax87_crush2.wav
